# ✏️ 47장 에러 처리

## 📌 47.1 에러 처리의 필요성

- 에러를 방치하면 프로그램은 강제 종료된다.
- 직접적으로 에러를 발생시키지 않는 예외 상황도 적절히 대응해야 한다.
  - null이 나오는 경우 단축 평가나 옵셔널 체이닝 연산자 ?.가 없다면 에러가 될 수 있다.
    ```
    // DOM에 button 요소가 존재하지 않으면 querySelector 메서드는 에러를 발생시키지 않고 null을 반환한다.

    const $button = document.querySelector('button'); // null
    $button.classList.add('disabled'); // TypeError: Cannot read property 'classList' of null
    ```
- try... catch문으로 에러에 적절하게 대응할 수 있다.

## 📌 47.2 try... cathch... finally문

- 에러를 처리하는 방법
  - 예외 상황 시 반환하는 값(null, -1)을 if문, 단축 평가, 옵셔널 체이닝 연산자로 확이해 처리하는 방법
  - 에러 처리 코드를 미리 등록하고 에러가 발생하면 해당 부분으로 점프하도록 하는 방법
- try... catch... finally문은 두 번째 방법에 해당한다.
- finally문은 생략할 수 있다.

```
try{
  // 실행할 코드(에러가 발생할 가능성이 있는 코드)
} catch (err) {
  // try 코드 블록에서 에러가 발생하면 이 코드 블록의 코드가 실행된다.
  // err에는 try 코드 블록에서 발생한 Error 객체가 전달된다.
} finally {
  // 에러 발생과 상관없이 반드시 한 번 실행된다.
}
```

- try 코드 블록이 먼저 실행되고, 에러가 발생하면 발생한 에러는 catch문의 err 변수로 전달된다.
- catch 코드 블록이 실행되고 에러 객체가 전달된다. 이는 catch 코드 블록에서만 유효하다.
- finally 코드 블록은 에러 발생 여부와 관계 없이 반드시 한 번 실행된다.

## 📌 47.3 Error 객체

- Error 생성자 함수는 에러 객체를 생성한다.
- Error 생성자 함수에는 에러를 설명하는 에러 메세지를 인수로 전달할 수 있다.

```
const error = new Error('invalid');
```

- 에러 객체는 message 프로퍼티와 stack 프로퍼티를 갖는다.
  - message 프로퍼티의 값은 Error 생성자 함수가 인수로 전달한 에러 메세지다.
  - stack 프로퍼티의 값은 에러를 발생시킨 콜 스택의 호출 정보를 나타내는 문자열이다. (디버깅 목적)
- JS의 Error 생성자 함수는 7개의 에러 객체를 생성할 수 있으며 생성된 에러 객체의 프로토타입은 모두 Error.prototype을 상속 받는다.

| 생성자 함수    | 인스턴스                                                       |
| -------------- | -------------------------------------------------------------- |
| Error          | 일반적인 에러 객체                                             |
| SyntaxError    | JS 문법에 맞지 않는 문을 해석할 때 발생                        |
| ReferenceError | 참조할 수 없는 식별자를 참조할 때 발생                         |
| TypeError      | 피연산자 또는 인수의 데이터 값이 유효하지 않을 때 발생         |
| RangeError     | 숫자값의 허용 범위를 벗어났을 때 발생                          |
| URIError       | encodeURI 또는 decodeURI 함수에 부적절한 인수를 전달할 때 발생 |
| EvalError      | eval 함수에서 발생하는 에러 객체                               |

```
1 @ 1;    // SyntaxError: Invalid or unexpected token
foo();    // ReferenceError: foo is not defined
null.foo; // TypeError: Cannot read property 'foo' of null
new Array(-1); // RangeError: Invalid array length
decodeURIComponent('%'); // URIError: URI malformed
```

## 📌 47.4 throw문

- Error 생성자 함수로 에러 객체를 생성한다고 발생하는 것은 아니다.
- 에러를 발생 시키려면 try 코드 블록에서 throw문으로 에러 객체를 던져야 한다.
- throw문의 표현식은 어떤 값이든 무관하지만 일반적으로 에러 객체를 지정한다.
- 에러를 던지면 catch문의 에러 변수가 생성되고 던져진 에러 객체가 할당된 후 catch 코드 블록이 실행된다.
- p.891 참고

```
try {
  // 에러 객체를 던지면 catch 코드 블록이 실행되기 시작한다.
  throw new Error('something wrong');
} catch (error) {
  console.log(error); // Error: something wrong
}
```

## 📌 47.5 에러의 전파

- 에러는 호출자 방향으로 전파된다. (=콜 스택의 아래 방향으로 전파된다.)

```
const foo = () => {
  throw Error('foo에서 발생한 에러'); // ④
};

const bar = () => {
  foo(); // ③
};

const baz = () => {
  bar(); // ②
};

try {
  baz(); // ①
} catch (err) {
  console.error(err);
}
```

- throw된 에러를 캐치하지 않으면 호출자 방향으로 전파된다.
- 만약 캐치하지 않으면 프로그램은 강제 종료된다.
- 주의할 점은 비동기 함수인 setTimeout이나 프로미스 후속 처리 메서드의 콜백 함수는 **호출자가 없다는 것이다.**
  - 이들은 태스크 큐나 마이크로태스크 큐에 일시 저장되었다가 콜 스택이 비면 이벤트 루프에 의해 콜 스택으로 푸시되어 실행된다.
  - 이 때 콜 스택에 푸시된 콜백 함수의 실행 컨텍스트는 콜 스택의 가장 하부에 존재한다.
  - 따라서 에러를 전파할 호출자가 존재하지 않는다.
